2024-01-04 10:02:01,318 ERROR: Exception on /register [POST] [in C:\Users\Gio\Documents\GitHub\planner\venv\Lib\site-packages\flask\app.py:1744]
Traceback (most recent call last):
  File "C:\Users\Gio\Documents\GitHub\planner\venv\Lib\site-packages\sqlalchemy\engine\base.py", line 1964, in _exec_single_context
    self.dialect.do_execute(
  File "C:\Users\Gio\Documents\GitHub\planner\venv\Lib\site-packages\sqlalchemy\engine\default.py", line 748, in do_execute
    cursor.execute(statement, parameters)
sqlite3.OperationalError: no such table: user

The above exception was the direct cause of the following exception:

Traceback (most recent call last):
  File "C:\Users\Gio\Documents\GitHub\planner\venv\Lib\site-packages\flask\app.py", line 2528, in wsgi_app
    response = self.full_dispatch_request()
               ^^^^^^^^^^^^^^^^^^^^^^^^^^^^
  File "C:\Users\Gio\Documents\GitHub\planner\venv\Lib\site-packages\flask\app.py", line 1825, in full_dispatch_request
    rv = self.handle_user_exception(e)
         ^^^^^^^^^^^^^^^^^^^^^^^^^^^^^
  File "C:\Users\Gio\Documents\GitHub\planner\venv\Lib\site-packages\flask\app.py", line 1823, in full_dispatch_request
    rv = self.dispatch_request()
         ^^^^^^^^^^^^^^^^^^^^^^^
  File "C:\Users\Gio\Documents\GitHub\planner\venv\Lib\site-packages\flask\app.py", line 1799, in dispatch_request
    return self.ensure_sync(self.view_functions[rule.endpoint])(**view_args)
           ^^^^^^^^^^^^^^^^^^^^^^^^^^^^^^^^^^^^^^^^^^^^^^^^^^^^^^^^^^^^^^^^^
  File "C:\Users\Gio\Documents\GitHub\planner\app\routes.py", line 80, in register
    if form.validate_on_submit():
       ^^^^^^^^^^^^^^^^^^^^^^^^^
  File "C:\Users\Gio\Documents\GitHub\planner\venv\Lib\site-packages\flask_wtf\form.py", line 86, in validate_on_submit
    return self.is_submitted() and self.validate(extra_validators=extra_validators)
                                   ^^^^^^^^^^^^^^^^^^^^^^^^^^^^^^^^^^^^^^^^^^^^^^^^
  File "C:\Users\Gio\Documents\GitHub\planner\venv\Lib\site-packages\wtforms\form.py", line 329, in validate
    return super().validate(extra)
           ^^^^^^^^^^^^^^^^^^^^^^^
  File "C:\Users\Gio\Documents\GitHub\planner\venv\Lib\site-packages\wtforms\form.py", line 146, in validate
    if not field.validate(self, extra):
           ^^^^^^^^^^^^^^^^^^^^^^^^^^^
  File "C:\Users\Gio\Documents\GitHub\planner\venv\Lib\site-packages\wtforms\fields\core.py", line 242, in validate
    stop_validation = self._run_validation_chain(form, chain)
                      ^^^^^^^^^^^^^^^^^^^^^^^^^^^^^^^^^^^^^^^
  File "C:\Users\Gio\Documents\GitHub\planner\venv\Lib\site-packages\wtforms\fields\core.py", line 262, in _run_validation_chain
    validator(form, self)
  File "C:\Users\Gio\Documents\GitHub\planner\app\forms.py", line 23, in validate_username
    user = User.query.filter_by(username=username.data).first()
           ^^^^^^^^^^^^^^^^^^^^^^^^^^^^^^^^^^^^^^^^^^^^^^^^^^^^
  File "C:\Users\Gio\Documents\GitHub\planner\venv\Lib\site-packages\sqlalchemy\orm\query.py", line 2752, in first
    return self.limit(1)._iter().first()  # type: ignore
           ^^^^^^^^^^^^^^^^^^^^^
  File "C:\Users\Gio\Documents\GitHub\planner\venv\Lib\site-packages\sqlalchemy\orm\query.py", line 2855, in _iter
    result: Union[ScalarResult[_T], Result[_T]] = self.session.execute(
                                                  ^^^^^^^^^^^^^^^^^^^^^
  File "C:\Users\Gio\Documents\GitHub\planner\venv\Lib\site-packages\sqlalchemy\orm\session.py", line 2229, in execute
    return self._execute_internal(
           ^^^^^^^^^^^^^^^^^^^^^^^
  File "C:\Users\Gio\Documents\GitHub\planner\venv\Lib\site-packages\sqlalchemy\orm\session.py", line 2124, in _execute_internal
    result: Result[Any] = compile_state_cls.orm_execute_statement(
                          ^^^^^^^^^^^^^^^^^^^^^^^^^^^^^^^^^^^^^^^^
  File "C:\Users\Gio\Documents\GitHub\planner\venv\Lib\site-packages\sqlalchemy\orm\context.py", line 253, in orm_execute_statement
    result = conn.execute(
             ^^^^^^^^^^^^^
  File "C:\Users\Gio\Documents\GitHub\planner\venv\Lib\site-packages\sqlalchemy\engine\base.py", line 1414, in execute
    return meth(
           ^^^^^
  File "C:\Users\Gio\Documents\GitHub\planner\venv\Lib\site-packages\sqlalchemy\sql\elements.py", line 486, in _execute_on_connection
    return connection._execute_clauseelement(
           ^^^^^^^^^^^^^^^^^^^^^^^^^^^^^^^^^^
  File "C:\Users\Gio\Documents\GitHub\planner\venv\Lib\site-packages\sqlalchemy\engine\base.py", line 1638, in _execute_clauseelement
    ret = self._execute_context(
          ^^^^^^^^^^^^^^^^^^^^^^
  File "C:\Users\Gio\Documents\GitHub\planner\venv\Lib\site-packages\sqlalchemy\engine\base.py", line 1842, in _execute_context
    return self._exec_single_context(
           ^^^^^^^^^^^^^^^^^^^^^^^^^^
  File "C:\Users\Gio\Documents\GitHub\planner\venv\Lib\site-packages\sqlalchemy\engine\base.py", line 1983, in _exec_single_context
    self._handle_dbapi_exception(
  File "C:\Users\Gio\Documents\GitHub\planner\venv\Lib\site-packages\sqlalchemy\engine\base.py", line 2326, in _handle_dbapi_exception
    raise sqlalchemy_exception.with_traceback(exc_info[2]) from e
  File "C:\Users\Gio\Documents\GitHub\planner\venv\Lib\site-packages\sqlalchemy\engine\base.py", line 1964, in _exec_single_context
    self.dialect.do_execute(
  File "C:\Users\Gio\Documents\GitHub\planner\venv\Lib\site-packages\sqlalchemy\engine\default.py", line 748, in do_execute
    cursor.execute(statement, parameters)
sqlalchemy.exc.OperationalError: (sqlite3.OperationalError) no such table: user
[SQL: SELECT user.id AS user_id, user.username AS user_username, user.email AS user_email, user.password_hash AS user_password_hash, user.about_me AS user_about_me, user.last_seen AS user_last_seen 
FROM user 
WHERE user.username = ?
 LIMIT ? OFFSET ?]
[parameters: ('gio', 1, 0)]
(Background on this error at: https://sqlalche.me/e/20/e3q8)
2024-01-04 10:02:19,580 INFO: ToDoList Startup [in C:\Users\Gio\Documents\GitHub\planner\app\__init__.py:31]
2024-01-04 10:02:57,773 INFO: ToDoList Startup [in C:\Users\Gio\Documents\GitHub\planner\app\__init__.py:31]
2024-01-04 10:04:15,654 INFO: ToDoList Startup [in C:\Users\Gio\Documents\GitHub\planner\app\__init__.py:31]
2024-01-04 10:04:19,521 INFO: ToDoList Startup [in C:\Users\Gio\Documents\GitHub\planner\app\__init__.py:31]
2024-01-04 10:04:22,529 INFO: ToDoList Startup [in C:\Users\Gio\Documents\GitHub\planner\app\__init__.py:31]
2024-01-04 10:05:35,386 INFO: ToDoList Startup [in C:\Users\Gio\Documents\GitHub\planner\app\__init__.py:31]
2024-01-04 10:05:47,047 INFO: ToDoList Startup [in C:\Users\Gio\Documents\GitHub\planner\app\__init__.py:31]
