2024-01-04 11:15:21,414 ERROR: Exception on /user/gio [GET] [in C:\Users\Gio\Documents\GitHub\planner\venv\Lib\site-packages\flask\app.py:1744]
Traceback (most recent call last):
  File "C:\Users\Gio\Documents\GitHub\planner\venv\Lib\site-packages\flask\app.py", line 2528, in wsgi_app
    response = self.full_dispatch_request()
               ^^^^^^^^^^^^^^^^^^^^^^^^^^^^
  File "C:\Users\Gio\Documents\GitHub\planner\venv\Lib\site-packages\flask\app.py", line 1825, in full_dispatch_request
    rv = self.handle_user_exception(e)
         ^^^^^^^^^^^^^^^^^^^^^^^^^^^^^
  File "C:\Users\Gio\Documents\GitHub\planner\venv\Lib\site-packages\flask\app.py", line 1823, in full_dispatch_request
    rv = self.dispatch_request()
         ^^^^^^^^^^^^^^^^^^^^^^^
  File "C:\Users\Gio\Documents\GitHub\planner\venv\Lib\site-packages\flask\app.py", line 1799, in dispatch_request
    return self.ensure_sync(self.view_functions[rule.endpoint])(**view_args)
           ^^^^^^^^^^^^^^^^^^^^^^^^^^^^^^^^^^^^^^^^^^^^^^^^^^^^^^^^^^^^^^^^^
  File "C:\Users\Gio\Documents\GitHub\planner\venv\Lib\site-packages\flask_login\utils.py", line 290, in decorated_view
    return current_app.ensure_sync(func)(*args, **kwargs)
           ^^^^^^^^^^^^^^^^^^^^^^^^^^^^^^^^^^^^^^^^^^^^^^
  File "C:\Users\Gio\Documents\GitHub\planner\app\routes.py", line 97, in user
    return render_template('user.html', user=user, todos=todos,
           ^^^^^^^^^^^^^^^^^^^^^^^^^^^^^^^^^^^^^^^^^^^^^^^^^^^^
  File "C:\Users\Gio\Documents\GitHub\planner\venv\Lib\site-packages\flask\templating.py", line 147, in render_template
    return _render(app, template, context)
           ^^^^^^^^^^^^^^^^^^^^^^^^^^^^^^^
  File "C:\Users\Gio\Documents\GitHub\planner\venv\Lib\site-packages\flask\templating.py", line 130, in _render
    rv = template.render(context)
         ^^^^^^^^^^^^^^^^^^^^^^^^
  File "C:\Users\Gio\Documents\GitHub\planner\venv\Lib\site-packages\jinja2\environment.py", line 1301, in render
    self.environment.handle_exception()
  File "C:\Users\Gio\Documents\GitHub\planner\venv\Lib\site-packages\jinja2\environment.py", line 936, in handle_exception
    raise rewrite_traceback_stack(source=source)
  File "C:\Users\Gio\Documents\GitHub\planner\app\templates\user.html", line 1, in top-level template code
    {% extends "base.html" %}
  File "C:\Users\Gio\Documents\GitHub\planner\app\templates\base.html", line 24, in top-level template code
    {% block content %}
  File "C:\Users\Gio\Documents\GitHub\planner\app\templates\base.html", line 25, in block 'content'
    {% block navbar %}
  File "C:\Users\Gio\Documents\GitHub\planner\venv\Lib\site-packages\jinja2\utils.py", line 83, in from_obj
    if hasattr(obj, "jinja_pass_arg"):
       ^^^^^^^^^^^^^^^^^^^^^^^^^^^^^^
jinja2.exceptions.UndefinedError: 'get_render_messages' is undefined
2024-01-04 11:15:39,109 INFO: ToDoList Startup [in C:\Users\Gio\Documents\GitHub\planner\app\__init__.py:31]
2024-01-04 11:15:39,670 ERROR: Exception on /user/gio [GET] [in C:\Users\Gio\Documents\GitHub\planner\venv\Lib\site-packages\flask\app.py:1744]
Traceback (most recent call last):
  File "C:\Users\Gio\Documents\GitHub\planner\venv\Lib\site-packages\flask\app.py", line 2528, in wsgi_app
    response = self.full_dispatch_request()
               ^^^^^^^^^^^^^^^^^^^^^^^^^^^^
  File "C:\Users\Gio\Documents\GitHub\planner\venv\Lib\site-packages\flask\app.py", line 1825, in full_dispatch_request
    rv = self.handle_user_exception(e)
         ^^^^^^^^^^^^^^^^^^^^^^^^^^^^^
  File "C:\Users\Gio\Documents\GitHub\planner\venv\Lib\site-packages\flask\app.py", line 1823, in full_dispatch_request
    rv = self.dispatch_request()
         ^^^^^^^^^^^^^^^^^^^^^^^
  File "C:\Users\Gio\Documents\GitHub\planner\venv\Lib\site-packages\flask\app.py", line 1799, in dispatch_request
    return self.ensure_sync(self.view_functions[rule.endpoint])(**view_args)
           ^^^^^^^^^^^^^^^^^^^^^^^^^^^^^^^^^^^^^^^^^^^^^^^^^^^^^^^^^^^^^^^^^
  File "C:\Users\Gio\Documents\GitHub\planner\venv\Lib\site-packages\flask_login\utils.py", line 290, in decorated_view
    return current_app.ensure_sync(func)(*args, **kwargs)
           ^^^^^^^^^^^^^^^^^^^^^^^^^^^^^^^^^^^^^^^^^^^^^^
  File "C:\Users\Gio\Documents\GitHub\planner\app\routes.py", line 97, in user
    return render_template('user.html', user=user, todos=todos,
           ^^^^^^^^^^^^^^^^^^^^^^^^^^^^^^^^^^^^^^^^^^^^^^^^^^^^
  File "C:\Users\Gio\Documents\GitHub\planner\venv\Lib\site-packages\flask\templating.py", line 147, in render_template
    return _render(app, template, context)
           ^^^^^^^^^^^^^^^^^^^^^^^^^^^^^^^
  File "C:\Users\Gio\Documents\GitHub\planner\venv\Lib\site-packages\flask\templating.py", line 130, in _render
    rv = template.render(context)
         ^^^^^^^^^^^^^^^^^^^^^^^^
  File "C:\Users\Gio\Documents\GitHub\planner\venv\Lib\site-packages\jinja2\environment.py", line 1301, in render
    self.environment.handle_exception()
  File "C:\Users\Gio\Documents\GitHub\planner\venv\Lib\site-packages\jinja2\environment.py", line 936, in handle_exception
    raise rewrite_traceback_stack(source=source)
  File "C:\Users\Gio\Documents\GitHub\planner\app\templates\user.html", line 1, in top-level template code
    {% extends "base.html" %}
  File "C:\Users\Gio\Documents\GitHub\planner\app\templates\base.html", line 24, in top-level template code
    {% block content %}
  File "C:\Users\Gio\Documents\GitHub\planner\app\templates\base.html", line 25, in block 'content'
    {% block navbar %}
  File "C:\Users\Gio\Documents\GitHub\planner\venv\Lib\site-packages\jinja2\utils.py", line 83, in from_obj
    if hasattr(obj, "jinja_pass_arg"):
       ^^^^^^^^^^^^^^^^^^^^^^^^^^^^^^
jinja2.exceptions.UndefinedError: 'render_messages' is undefined
2024-01-04 11:18:04,963 INFO: ToDoList Startup [in C:\Users\Gio\Documents\GitHub\planner\app\__init__.py:31]
2024-01-04 11:18:13,412 INFO: ToDoList Startup [in C:\Users\Gio\Documents\GitHub\planner\app\__init__.py:31]
2024-01-04 11:19:49,592 INFO: ToDoList Startup [in C:\Users\Gio\Documents\GitHub\planner\app\__init__.py:31]
2024-01-04 11:20:31,310 INFO: ToDoList Startup [in C:\Users\Gio\Documents\GitHub\planner\app\__init__.py:31]
2024-01-04 11:20:32,317 ERROR: Exception on /index [GET] [in C:\Users\Gio\Documents\GitHub\planner\venv\Lib\site-packages\flask\app.py:1744]
Traceback (most recent call last):
  File "C:\Users\Gio\Documents\GitHub\planner\venv\Lib\site-packages\flask\app.py", line 2528, in wsgi_app
    response = self.full_dispatch_request()
               ^^^^^^^^^^^^^^^^^^^^^^^^^^^^
  File "C:\Users\Gio\Documents\GitHub\planner\venv\Lib\site-packages\flask\app.py", line 1825, in full_dispatch_request
    rv = self.handle_user_exception(e)
         ^^^^^^^^^^^^^^^^^^^^^^^^^^^^^
  File "C:\Users\Gio\Documents\GitHub\planner\venv\Lib\site-packages\flask\app.py", line 1823, in full_dispatch_request
    rv = self.dispatch_request()
         ^^^^^^^^^^^^^^^^^^^^^^^
  File "C:\Users\Gio\Documents\GitHub\planner\venv\Lib\site-packages\flask\app.py", line 1799, in dispatch_request
    return self.ensure_sync(self.view_functions[rule.endpoint])(**view_args)
           ^^^^^^^^^^^^^^^^^^^^^^^^^^^^^^^^^^^^^^^^^^^^^^^^^^^^^^^^^^^^^^^^^
  File "C:\Users\Gio\Documents\GitHub\planner\venv\Lib\site-packages\flask_login\utils.py", line 290, in decorated_view
    return current_app.ensure_sync(func)(*args, **kwargs)
           ^^^^^^^^^^^^^^^^^^^^^^^^^^^^^^^^^^^^^^^^^^^^^^
  File "C:\Users\Gio\Documents\GitHub\planner\app\routes.py", line 21, in index
    return render_template('index.html', title='Home',
           ^^^^^^^^^^^^^^^^^^^^^^^^^^^^^^^^^^^^^^^^^^^
  File "C:\Users\Gio\Documents\GitHub\planner\venv\Lib\site-packages\flask\templating.py", line 147, in render_template
    return _render(app, template, context)
           ^^^^^^^^^^^^^^^^^^^^^^^^^^^^^^^
  File "C:\Users\Gio\Documents\GitHub\planner\venv\Lib\site-packages\flask\templating.py", line 130, in _render
    rv = template.render(context)
         ^^^^^^^^^^^^^^^^^^^^^^^^
  File "C:\Users\Gio\Documents\GitHub\planner\venv\Lib\site-packages\jinja2\environment.py", line 1301, in render
    self.environment.handle_exception()
  File "C:\Users\Gio\Documents\GitHub\planner\venv\Lib\site-packages\jinja2\environment.py", line 936, in handle_exception
    raise rewrite_traceback_stack(source=source)
  File "C:\Users\Gio\Documents\GitHub\planner\app\templates\index.html", line 1, in top-level template code
    {% extends "base.html" %}
  File "C:\Users\Gio\Documents\GitHub\planner\app\templates\base.html", line 25, in top-level template code
    {% block content %}
  File "C:\Users\Gio\Documents\GitHub\planner\app\templates\base.html", line 26, in block 'content'
    {% block navbar %}
  File "C:\Users\Gio\Documents\GitHub\planner\app\templates\base.html", line 31, in block 'navbar'
    {{ render_nav_item('about', 'About') }}
    ^^^^^^^^^^^^^^^^^^^^^^^^^
  File "C:\Users\Gio\Documents\GitHub\planner\venv\Lib\site-packages\jinja2\runtime.py", line 777, in _invoke
    rv = self._func(*arguments)
         ^^^^^^^^^^^^^^^^^^^^^^
  File "C:\Users\Gio\Documents\GitHub\planner\venv\Lib\site-packages\flask_bootstrap\templates\base\nav.html", line 5, in template
    href="{{ url_for(endpoint, **kwargs) }}">
    ^^^^^^^^^^^^^^^^^^^^^^^^^
  File "C:\Users\Gio\Documents\GitHub\planner\venv\Lib\site-packages\flask\app.py", line 2034, in url_for
    return self.handle_url_build_error(error, endpoint, values)
           ^^^^^^^^^^^^^^^^^^^^^^^^^^^^^^^^^^^^^^^^^^^^^^^^^^^^
  File "C:\Users\Gio\Documents\GitHub\planner\venv\Lib\site-packages\flask\app.py", line 2023, in url_for
    rv = url_adapter.build(  # type: ignore[union-attr]
         ^^^^^^^^^^^^^^^^^^^^^^^^^^^^^^^^^^^^^^^^^^^^^^
  File "C:\Users\Gio\Documents\GitHub\planner\venv\Lib\site-packages\werkzeug\routing\map.py", line 917, in build
    raise BuildError(endpoint, values, method, self)
werkzeug.routing.exceptions.BuildError: Could not build url for endpoint 'about'. Did you mean 'logout' instead?
